Workbook

Sheet Sheet1
A1: ID | B1: Hora de início | C1: Hora de conclusão | D1: Email | E1: Nome | F1: Hora da última modificação | G1: Para qual obra deseja regularizar um contrato? | H1: Qual o número da Solicitação? | I1: A solicitação está aprovada? | J1: Qual a descrição Geral do Serviço? | K1: Essa regularização faz parte da carteira de qual setor? | L1: Qual regularização deseja realizar? | M1: Qual o número do contrato no Sienge? | N1: Deseja pontuar mais alguma observação da regularização em questão? | O1: Qual o número do credor? | P1: Qual a descrição do Credor? | Q1: Qual a data de inicio do contrato? | R1: Qual a data de término do contrato? | S1: Adicione uma nota fiscal modelo do fornecedor | T1: Qual o tipo de contrato? | U1: Haverá caução ou retenção nesse contrato? | V1: Deseja pontuar mais alguma observação da elaboração em questão? | W1: Especifique o motivo da compra ter sido feita diretamente pela obra | X1: Especifique a Categoria: | Y1: Adicione uma nota fiscal dos materiais comprados ou proposta final negociada | Z1: Adicione um comprovante de autorização do coordenador da obra: | AA1: Qual o número do credor cadastrado? | AB1: Qual o CNPJ do Credor Cadastrado? | AC1: Qual a descrição código do insumo, quantidade e preço unitário. | AD1: Condição de pagamento negociada | AE1: Deseja pontuar mais alguma observação do pedido em questão?
A2: 29 | B2: 45749.383 | C2: 45749.384 | D2: anonymous | G2: Royal Palace | H2: 72280 | I2: Sim | J2: lavagem fachada | L2: Aditivo de Contrato | M2: CS/960079
A3: 30 | B3: 45749.421 | C3: 45749.456 | D3: anonymous | G3: Royal Plaza | H3: 71774 | I3: Sim | J3: Impermeabilização apto: R$ 13,60/m2 CONTRAPISO: R$ 25,00/m2 | L3: Aditivo de Contrato | M3: CS/2420134
A4: 36 | B4: 45755.476 | C4: 45755.48 | D4: rafael.souza@lbx.com.br | E4: Rafael Barbosa Ramalho de Souza | G4: Royal Legacy | H4: 72790 | I4: Sim | J4: Medição de energia COPEL | L4: Elaboração de Contrato novo | O4: 191 | P4: COPEL | Q4: 45757 | R4: 45848 | S4: https://lbxconstrucao-my.sharepoint.com/personal/lucas_silva_lbx_com_br/Documents/Aplicativos/Microsoft%20Forms/Regulariza%C3%A7%C3%A3o%20de%20contratos%20Sienge%201/Pergunta/LUZ%20(1)_Rafael%20Barbosa%20Ramal.jpeg | T4: Normal
A5: 37 | B5: 45755.573 | C5: 45755.589 | D5: guilherme.aoyama@lbx.com.br | E5: Guilherme Aoyama | G5: Forte de Arundel | H5: 72291 | I5: Sim | J5: Limpeza de canteiro de obras | L5: Elaboração de Contrato novo | O5: 15971 | P5: FLAVIA CARNEIRO DE CARVALHO NEPONUCENA | Q5: 45747 | R5: 45930 | S5: https://lbxconstrucao-my.sharepoint.com/personal/lucas_silva_lbx_com_br/Documents/Aplicativos/Microsoft%20Forms/Regulariza%C3%A7%C3%A3o%20de%20contratos%20Sienge%201/Pergunta/669-cellis%20park%20900189330678_Guilherme%20Aoyama.pdf | T5: Spot
A6: 38 | B6: 45755.589 | C6: 45755.603 | D6: guilherme.aoyama@lbx.com.br | E6: Guilherme Aoyama | G6: Forte de Arundel | H6: 72411 | I6: Sim | J6: Serviço de impermeabilização, rejunte, limpeza grossa, limpeza fina | L6: Elaboração de Contrato novo | O6: 14266 | P6: LF ACABAMENTOS LTDA | Q6: 45809 | R6: 46082 | S6: https://lbxconstrucao-my.sharepoint.com/personal/lucas_silva_lbx_com_br/Documents/Aplicativos/Microsoft%20Forms/Regulariza%C3%A7%C3%A3o%20de%20contratos%20Sienge%201/Pergunta/LBX_Guilherme%20Aoyama.pdf | T6: Normal
A7: 39 | B7: 45755.603 | C7: 45755.605 | D7: guilherme.aoyama@lbx.com.br | E7: Guilherme Aoyama | G7: Forte de Arundel | H7: 71017 | I7: Sim | J7: Execução de chapisco para gesso e gesso corrido | L7: Elaboração de Contrato novo | O7: 16209 | P7: G. M. SOLUÇÕES TERMOACUSTICAS LTDA | Q7: 45792 | R7: 46157 | S7: https://lbxconstrucao-my.sharepoint.com/personal/lucas_silva_lbx_com_br/Documents/Aplicativos/Microsoft%20Forms/Regulariza%C3%A7%C3%A3o%20de%20contratos%20Sienge%201/Pergunta/ENTREVIAS%20%20NF%2046..._Guilherme%20Aoyama.pdf | T7: Normal
A8: 40 | B8: 45761.409 | C8: 45761.41 | D8: eduardo.silva@lbx.com.br | E8: Eduardo Marques da Silva | G8: Royal Legacy | H8: 73155 | I8: Não | J8: Pintura | L8: Aditivo de Contrato | M8: ct/1470022
A9: 41 | B9: 45761.582 | C9: 45761.589 | D9: rafael.souza@lbx.com.br | E9: Rafael Barbosa Ramalho de Souza | G9: Royal Legacy | H9: 70906 | I9: Sim | J9: SERVIÇOS GERAIS DE CONSTRUÇÃO CIVIL | L9: Elaboração de Contrato novo | O9: 16293 | P9: EPOCA PRESTADORA DE SERVICOS LTDA | Q9: 45740 | R9: 45808 | S9: https://lbxconstrucao-my.sharepoint.com/personal/lucas_silva_lbx_com_br/Documents/Aplicativos/Microsoft%20Forms/Regulariza%C3%A7%C3%A3o%20de%20contratos%20Sienge%201/Pergunta/teste_Rafael%20Barbosa%20Ramal.pdf | T9: Normal
A10: 42 | B10: 45761.589 | C10: 45761.592 | D10: rafael.souza@lbx.com.br | E10: Rafael Barbosa Ramalho de Souza | G10: Royal Legacy | H10: 73100 | I10: Sim | J10: FORNECIMENTO DE MARMITA | L10: Elaboração de Contrato novo | O10: 15036 | P10: LUIZ CARLOS VASQUEZ (VIVIAN) | Q10: 45761 | R10: 45838 | S10: https://lbxconstrucao-my.sharepoint.com/personal/lucas_silva_lbx_com_br/Documents/Aplicativos/Microsoft%20Forms/Regulariza%C3%A7%C3%A3o%20de%20contratos%20Sienge%201/Pergunta/410830422549530810001730000000000032250322611_Rafael%20Barbosa%20Ramal.pdf | T10: Normal
A11: 43 | B11: 45763.583 | C11: 45763.584 | D11: rafael.souza@lbx.com.br | E11: Rafael Barbosa Ramalho de Souza | G11: Royal Legacy | H11: 73368 | I11: Não | J11: LAMINADO E PORTAS DE MADEIRA | L11: Aditivo de Contrato | M11: CS/1470088 | N11: NÃO
A12: 44 | B12: 45763.621 | C12: 45763.622 | D12: rafael.souza@lbx.com.br | E12: Rafael Barbosa Ramalho de Souza | G12: Royal Legacy | H12: 73377 | I12: Não | J12: INSTALAÇÃO DE ESQUADRIAS | L12: Aditivo de Contrato | M12: CS/1470127 | N12: NÃO
A13: 45 | B13: 45763.681 | C13: 45763.682 | D13: rafael.souza@lbx.com.br | E13: Rafael Barbosa Ramalho de Souza | G13: Royal Legacy | H13: 73403 | I13: Não | J13: MONITORAMENTO REMOTO | L13: Aditivo de Contrato | M13: CT/1470171 | N13: NÃO
A14: 46 | B14: 45763.699 | C14: 45763.699 | D14: rafael.souza@lbx.com.br | E14: Rafael Barbosa Ramalho de Souza | G14: Royal Legacy | H14: 73408 | I14: Não | J14: SERVICO DE DRYWALL | L14: Aditivo de Contrato | M14: CS/1470031 | N14: NÃO
A15: 47 | B15: 45764.349 | C15: 45764.351 | D15: rafael.souza@lbx.com.br | E15: Rafael Barbosa Ramalho de Souza | G15: Royal Legacy | H15: 73400 | I15: Sim | J15: INSTALAÇÃO DE REVESTIMENTO CERAMICO E CHECKLIST | L15: Elaboração de Contrato novo | O15: 11255 | P15: E. DA ROCHA | Q15: 45748 | R15: 45838 | S15: https://lbxconstrucao-my.sharepoint.com/personal/lucas_silva_lbx_com_br/Documents/Aplicativos/Microsoft%20Forms/Regulariza%C3%A7%C3%A3o%20de%20contratos%20Sienge%201/Pergunta/NF%20174%20-%20ROYAL%20PLAZA%20INCORPORADORA%20E%20CONSTRUT_Rafael%20Barbosa%20Ramal.pdf | T15: Normal | V15: NÃO
A16: 48 | B16: 45764.697 | C16: 45764.699 | D16: guilherme.aoyama@lbx.com.br | E16: Guilherme Aoyama | G16: Forte de Arundel | H16: 73437 | I16: Sim | J16: Forma e desforma laje lazer cintamento | L16: Aditivo de Contrato | M16: CS/2550026
A17: 49 | B17: 45764.715 | C17: 45764.719 | D17: matheus.pereira@lbx.com.br | E17: Matheus Felipe Pereira | G17: Forte de Arundel | H17: 73139 | I17: Sim | J17: Serviço de manutenção cabo das câmeras rompido | L17: Aditivo de Contrato | M17: CS/2550016
A18: 50 | B18: 45769.632 | C18: 45769.632 | D18: rafael.souza@lbx.com.br | E18: Rafael Barbosa Ramalho de Souza | G18: Royal Legacy | H18: 73574 | I18: Não | J18: PINTURA | L18: Aditivo de Contrato | M18: CS/1470027 | N18: NÃO
A19: 51 | B19: 45770.333 | C19: 45770.334 | D19: rafael.souza@lbx.com.br | E19: Rafael Barbosa Ramalho de Souza | G19: Royal Legacy | H19: 73621 | I19: Não | J19: PINTURA | L19: Aditivo de Contrato | M19: CS/1470098 | N19: NÃO
A20: 52 | B20: 45770.376 | C20: 45770.376 | D20: rafael.souza@lbx.com.br | E20: Rafael Barbosa Ramalho de Souza | G20: Royal Legacy | H20: 73631 | I20: Não | J20: CHECKLIST | L20: Aditivo de Contrato | M20: CT/1470225 | N20: NÃO
A21: 53 | B21: 45770.405 | C21: 45770.406 | D21: rafael.souza@lbx.com.br | E21: Rafael Barbosa Ramalho de Souza | G21: Royal Legacy | H21: 73634 | I21: Não | J21: ASSENTAMENTO DE REVESTIMENTO | L21: Aditivo de Contrato | M21: CS/1470125 | N21: NÃO
A22: 54 | B22: 45770.408 | C22: 45770.409 | D22: leonardo.gottardo@lbx.com.br | E22: Leonardo Pientencoski Gottardo | G22: Forte dos Lagos | H22: 73614 | I22: Não | J22: Limpeza de caixas de agua - 9un | L22: Elaboração de Contrato novo | O22: 16488 | P22: AQUABRAS COMERCIO E MANUTENCAO DE EQUIPAMENTOS PARA TRATAMENTO DE AGUA LTDA | Q22: 45768 | R22: 45775 | S22: https://lbxconstrucao-my.sharepoint.com/personal/lucas_silva_lbx_com_br/Documents/Aplicativos/Microsoft%20Forms/Regulariza%C3%A7%C3%A3o%20de%20contratos%20Sienge%201/Pergunta/NF%20LBX%20(5)_Leonardo%20Pientencosk.pdf | T22: Spot
A23: 55 | B23: 45770.413 | C23: 45770.415 | D23: rafael.souza@lbx.com.br | E23: Rafael Barbosa Ramalho de Souza | G23: Royal Legacy | H23: 73639 | I23: Não | J23: PINTURA | L23: Aditivo de Contrato | M23: CT/1470222
A24: 56 | B24: 45770.567 | C24: 45770.567 | D24: rafael.souza@lbx.com.br | E24: Rafael Barbosa Ramalho de Souza | G24: Royal Legacy | H24: 73554 | I24: Sim | J24: POS FORMA | L24: Aditivo de Contrato | M24: CT/1470167 | N24: NÃO
A25: 57 | B25: 45770.688 | C25: 45770.689 | D25: rafael.souza@lbx.com.br | E25: Rafael Barbosa Ramalho de Souza | G25: Royal Legacy | H25: 73685 | I25: Não | J25: ELETRICA/HIDRAULICA | L25: Aditivo de Contrato | M25: CS/1470084 | N25: NÃO
A26: 58 | B26: 45770.736 | C26: 45770.736 | D26: rafael.souza@lbx.com.br | E26: Rafael Barbosa Ramalho de Souza | G26: Royal Legacy | H26: 73699 | I26: Não | J26: maquinas e equipamentos | L26: Aditivo de Contrato | M26: CS/1470075 | N26: não
A27: 59 | B27: 45771.323 | C27: 45771.325 | D27: rafael.souza@lbx.com.br | E27: Rafael Barbosa Ramalho de Souza | G27: Royal Legacy | H27: 73707 | I27: Não | J27: PINTURA GRADIL | L27: Aditivo de Contrato | M27: CS/1470033 | N27: NÃO
A28: 67 | B28: 45771.552 | C28: 45771.558 | D28: maria.santos@lbx.com.br | E28: Maria Angélica Garcia dos Santos | G28: Royal Ellus | H28: 73727 | I28: Sim | J28: Serviço de Instalação Elétrica | L28: Aditivo de Contrato | M28: CS/1070100
A29: 68 | B29: 45771.558 | C29: 45771.559 | D29: maria.santos@lbx.com.br | E29: Maria Angélica Garcia dos Santos | G29: Royal Ellus | H29: 73728 | I29: Sim | J29: Serviço de Instalação Elétrica | L29: Aditivo de Contrato | M29: CS/1070100
A30: 69 | B30: 45771.559 | C30: 45771.56 | D30: maria.santos@lbx.com.br | E30: Maria Angélica Garcia dos Santos | G30: Royal Ellus | H30: 73635 | I30: Sim | J30: Serviço de Instalação de Elétrica | L30: Aditivo de Contrato | M30: CS/1070100
A31: 70 | B31: 45771.592 | C31: 45771.592 | D31: rafael.souza@lbx.com.br | E31: Rafael Barbosa Ramalho de Souza | G31: Royal Legacy | H31: 73744 | I31: Não | J31: ALVENARIA | L31: Aditivo de Contrato | M31: CT/1470234 | N31: NÃO
A32: 71 | B32: 45771.647 | C32: 45771.648 | D32: rafael.souza@lbx.com.br | E32: Rafael Barbosa Ramalho de Souza | G32: Royal Legacy | H32: 73769 | I32: Não | J32: CHECKLIST E LIMPEZA | L32: Aditivo de Contrato | M32: CS/1470136 | N32: NÃO
A33: 72 | B33: 45772.551 | C33: 45772.582 | D33: emidio.neto@lbx.com.br | E33: Emídio de Sousa Estrela Neto | G33: Royal Porto dourado | H33: 71348 | I33: Sim | J33: Criação de Contrato de Alojamento | L33: Elaboração de Contrato novo | O33: 16517 | P33: Locação de Imóveis | Q33: 45726 | R33: 46171 | S33: https://lbxconstrucao-my.sharepoint.com/personal/lucas_silva_lbx_com_br/Documents/Aplicativos/Microsoft%20Forms/Regulariza%C3%A7%C3%A3o%20de%20contratos%20Sienge%201/Pergunta/Boleto%20Imobiliaria%20Uni%C3%A3o_Em%C3%ADdio%20de%20Sousa%20Estr.pdf | T33: Normal
A34: 73 | B34: 45772.634 | C34: 45772.634 | D34: hugo.silva@lbx.com.br | E34: Hugo Leonardo Oliveira da Silva | G34: Terra de Santa Cruz Unificado Maringá | H34: 73714 | I34: Sim | J34: Serviço de instalações elétricas | L34: Aditivo de Contrato | M34: CT/1010071
A35: 74 | B35: 45775.663 | C35: 45775.663 | D35: rafael.souza@lbx.com.br | E35: Rafael Barbosa Ramalho de Souza | G35: Royal Legacy | H35: 73460 | I35: Sim | J35: PINTURA | L35: Aditivo de Contrato | M35: CS/1470027 | N35: não
A36: 75 | B36: 45775.712 | C36: 45775.714 | D36: isabela.goncalves@lbx.com.br | E36: Isabela Adario Gonçales | G36: Royal Ellus | H36: 73671 | I36: Sim | J36: DESPESAS COM DESLOCAMENTO DE TERCEIRO PARA REALIZACAO DE SERVICOS (OBRA) | L36: Aditivo de Contrato | M36: CS/1070055
A37: 76 | B37: 45775.714 | C37: 45775.722 | D37: isabela.goncalves@lbx.com.br | E37: Isabela Adario Gonçales | G37: Royal Ellus | H37: SC 73904 | I37: Não | J37: LIMPEZA | L37: Aditivo de Contrato | M37: CT/1070163
A38: 78 | B38: 45778.383 | C38: 45778.386 | D38: maria.santos@lbx.com.br | E38: Maria Angélica Garcia dos Santos | G38: Royal Ellus | H38: 73839 | I38: Sim | J38: Serviço de Vigilância Remota Mensal | L38: Aditivo de Contrato | M38: CT/1070099
A39: 81 | B39: 45779.687 | C39: 45779.688 | D39: rafael.souza@lbx.com.br | E39: Rafael Barbosa Ramalho de Souza | G39: Royal Legacy | H39: 74229 | I39: Não | J39: ARGAMASSA ESTABILIZADA | L39: Aditivo de Contrato | M39: CS/1470053 | N39: NÃO
A40: 82 | B40: 45782.451 | C40: 45782.453 | D40: maria.santos@lbx.com.br | E40: Maria Angélica Garcia dos Santos | G40: Royal Ellus | H40: 73838 | I40: Sim | J40: Serviço de Instalação de bomba para Incêndio e Serviço de Instalação Eletrica/Hidraulica para Bombas/Sistema para Reservatório Elevado/Castelo | L40: Aditivo de Contrato | M40: CS/1070090
...

Sheet Especificação
A1: Obra | B1: Coordenador | C1: Fornecedor | D1: Insumo | E1: Data | F1: ValorTotal
A2: PORTO RICO - NEO WAVE | B2: Flavia Shigueoka | C2: RIO DEPOSITO DE MATERIAIS PARA CONSTRUCAO LTDA | D2: DISCO DE CORTE PARA FERRO | E2: 46149 | F2: 280.958
A3: MARINGA - FORTE DE ATHENA | B3: Lucas Gaspar | C3: F.B. LOMBARDI - FERRAGENS | D3: MATERIAL PARA EXECUCAO DE SERVICO | E3: 46149 | F3: 576.4
A4: MARINGA - FORTE DE ATHENA | B4: Lucas Gaspar | C4: COMERCIAL DE FERRAGENS COFEBRAL LTDA | D4: PARAFUSADEIRA FURADEIRA BOSCH GSB 180-LI 18V C/2 BATERIAS +1 CARREG. +1 MALETA | E4: 46149 | F4: 1254
A5: MARINGA - FORTE DE ATHENA | B5: Lucas Gaspar | C5: COMERCIAL DE FERRAGENS COFEBRAL LTDA | E5: 46149
A6: CASCAVEL - DUO VILLE RESIDENCE | B6: Diego Gomes | C6: OMORI E SUZAKI CASCAVEL ALUGUEL DE EQUIPAMENTOS LTDA. | D6: LOCACAO TRAVA DIAGONAL PARA ANDAIME | E6: 46149 | F6: 12
A7: CASCAVEL - DUO VILLE RESIDENCE | B7: Diego Gomes | C7: OMORI E SUZAKI CASCAVEL ALUGUEL DE EQUIPAMENTOS LTDA. | D7: LOCACAO PAINEL METALICO PARA ANDAIME | E7: 46149 | F7: 360
A8: CASCAVEL - DUO VILLE RESIDENCE | B8: Diego Gomes | C8: OMORI E SUZAKI CASCAVEL ALUGUEL DE EQUIPAMENTOS LTDA. | D8: LOCACAO SAPATA PARA ANDAIME | E8: 46149 | F8: 280
A9: CASCAVEL - DUO VILLE RESIDENCE | B9: Diego Gomes | C9: OMORI E SUZAKI CASCAVEL ALUGUEL DE EQUIPAMENTOS LTDA. | D9: LOCACAO PISO PLATAFORMA PARA ANDAIME | E9: 46149 | F9: 11
A10: CASCAVEL - DUO VILLE RESIDENCE | B10: Diego Gomes | C10: OMORI E SUZAKI CASCAVEL ALUGUEL DE EQUIPAMENTOS LTDA. | D10: LOCACAO DE ANDAIME MULTIDIRECIONAL | E10: 46149 | F10: 217
A11: CASCAVEL - DUO VILLE RESIDENCE | B11: Diego Gomes | C11: OMORI E SUZAKI CASCAVEL ALUGUEL DE EQUIPAMENTOS LTDA. | D11: LOCACAO DE ANDAIME MULTIDIRECIONAL | E11: 46149 | F11: 708
A12: CASCAVEL - DUO VILLE RESIDENCE | B12: Diego Gomes | C12: OMORI E SUZAKI CASCAVEL ALUGUEL DE EQUIPAMENTOS LTDA. | D12: LOCACAO PISO PLATAFORMA PARA ANDAIME | E12: 46149 | F12: 216
A13: PAIÇANDU - TERRA DE SANTA CRUZ | B13: Flavia Shigueoka | C13: MADEFORT MARINGA COMERCIO DE MADEIRAS EIRELI ME | D13: CAIBRO DE PINUS 5X5X1,0MT (ESTACA) | E13: 46149 | F13: 240
A14: PAIÇANDU - TERRA DE SANTA CRUZ | B14: Flavia Shigueoka | C14: ELETRONORTE MARINGA COM. FERRAMENTAS E SERVIÇOS | D14: SERVICO DE MANUTENCAO DE MAQUINAS E EQUIPAMENTOS | E14: 46149 | F14: 619
A15: PAIÇANDU - TERRA DE SANTA CRUZ | B15: Flavia Shigueoka | C15: ERICA KUMIKO OTA LOCACAO DE ANDAIMES LTDA | D15: LOCACAO DE ANDAIME TUBULAR | E15: 46149 | F15: 2234
A16: PARANAVAI - TERRA DE SANTA CRUZ II | B16: Flavia Shigueoka | C16: MARIA SONIA DOS REIS DE OLIVEIRA 48872784972 | D16: ACOES DE ENGAJAMENTO | E16: 46149 | F16: 655
A17: CASCAVEL - ROYAL PLAZA | B17: Eduardo Marques | C17: DGM COMERCIO DE UTILIDADES DOMÉSTICAS - EIRELI | D17: LOCACAO DE COMPACTADOR (SAPO) | E17: 46149 | F17: 1600
... A126: CASCAVEL - DUO VILLE RESIDENCE | B126: Diego Gomes | C126: EDFASS LIVRARIA E PAPELARIA LTDA | D126: CANETA PARA QUADRO BRANCO | E126: 46147 | F126: 14.7
A127: MARINGA - FORTE DE ATHENA | B127: Lucas Gaspar | C127: BR ENGENHARIA E OBRAS DE INFRAESTRUTURA LTDA | E127: 46147
A128: CASCAVEL - ROYAL PLAZA | B128: Eduardo Marques | C128: BIGOLIN MATERIAIS DE CONSTRUCAO LTDA | D128: ROLO PARA PINTURA | E128: 46147 | F128: 25.88
A129: CASCAVEL - ROYAL PLAZA | B129: Eduardo Marques | C129: BIGOLIN MATERIAIS DE CONSTRUCAO LTDA | D129: PINO ENGATE MACHO 1/4"&#148; | E129: 46147 | F129: 59.74
A130: CASCAVEL - ROYAL PLAZA | B130: Eduardo Marques | C130: BIGOLIN MATERIAIS DE CONSTRUCAO LTDA | D130: VALVULA PARA MICTORIO | E130: 46147 | F130: 398.1702
A131: ARAPONGAS - ROYAL PARADISE | B131: Gustavo Sana | C131: M F - EQUIPAMENTOS DE PROTECAO INDIVIDUAL E COLETIVO LTDA | D131: LUVA DE VAQUETA MISTA TAMANHO 7 | E131: 46147 | F131: 990
A132: ARAPONGAS - ROYAL PARADISE | B132: Gustavo Sana | C132: 65.707.166 FELIPE PORTILHO LOPES | D132: LANCHE/CAFE/REFEICAO EM OBRA | E132: 46147 | F132: 12255
A133: CASCAVEL - ROYAL PLAZA | B133: Eduardo Marques | C133: BIGOLIN MATERIAIS DE CONSTRUCAO LTDA | D133: ARGAMASSA COLANTE AC - II | E133: 46147 | F133: 2729.8
A134: CASCAVEL - DUO VILLE RESIDENCE | B134: Diego Gomes | C134: EDFASS LIVRARIA E PAPELARIA LTDA | D134: ISOPOR 1000X100X10MM | E134: 46147 | F134: 75
A135: CASCAVEL - ROYAL PLAZA | B135: Eduardo Marques | C135: BIGOLIN MATERIAIS DE CONSTRUCAO LTDA | D135: TUBO PVC ESGOTO PL 200MM | E135: 46147 | F135: 2180.54
A136: CASCAVEL - ROYAL PLAZA | B136: Eduardo Marques | C136: BIGOLIN MATERIAIS DE CONSTRUCAO LTDA | D136: MATERIAL PARA EXECUCAO SERVIÇO DE DRYWALL | E136: 46147 | F136: 697.5969
A137: CASCAVEL - ROYAL PLAZA | B137: Eduardo Marques | C137: BIGOLIN MATERIAIS DE CONSTRUCAO LTDA | D137: FILME DE PROTECAO ELETROSTATICO AUTO COLANTE 2,4M X 20M | E137: 46147 | F137: 1042.29
A138: CASCAVEL - DUO VILLE RESIDENCE | B138: Diego Gomes | C138: EDFASS LIVRARIA E PAPELARIA LTDA | D138: CANETA PARA QUADRO BRANCO | E138: 46147 | F138: 6.6
A139: CASCAVEL - DUO VILLE RESIDENCE | B139: Diego Gomes | C139: EDFASS LIVRARIA E PAPELARIA LTDA | D139: CANETA PARA QUADRO BRANCO | E139: 46147 | F139: 14.7
A140: CASCAVEL - ROYAL PLAZA | B140: Eduardo Marques | C140: BIGOLIN MATERIAIS DE CONSTRUCAO LTDA | D140: PINCEL PARA PINTURA | E140: 46147 | F140: 216.91
A141: CASCAVEL - ROYAL PLAZA | B141: Eduardo Marques | C141: BIGOLIN MATERIAIS DE CONSTRUCAO LTDA | E141: 46147
A142: CASCAVEL - ROYAL PLAZA | B142: Eduardo Marques | C142: BIGOLIN MATERIAIS DE CONSTRUCAO LTDA | D142: THINNER FORTE | E142: 46147 | F142: 358.09
A143: MARINGA - FORTE DE ATHENA | B143: Lucas Gaspar | C143: L. LOPES DE MORAES - COMERCIO DE FERRAMENTAS | D143: LOCACAO DE CAMINHAO MUNCK | E143: 46146 | F143: 2200
A144: MARINGA - FORTE DE ATHENA | B144: Lucas Gaspar | C144: L. LOPES DE MORAES - COMERCIO DE FERRAMENTAS | D144: LOCACAO DE CAMINHAO MUNCK | E144: 46146 | F144: 1650
A145: MARINGA - FORTE DE ATHENA | B145: Lucas Gaspar | C145: L. LOPES DE MORAES - COMERCIO DE FERRAMENTAS | D145: DESPESA COM DESLOCAMENTO DE MAQUINAS E EQUIPAMENTOS LOCADOS - DO FORNECEDOR ATE A OBRA | E145: 46146 | F145: 660
A146: MARINGA - FORTE DE ATHENA | B146: Lucas Gaspar | C146: WESLEY FERREIRA SILVA 07826489911 | E146: 46146
A147: TOLEDO - ROYAL PARK FOREST | B147: Diego Gomes | C147: MESTRE DA OBRA TOLEDO | D147: LOCACAO LIXADEIRA DE PAREDE / TETO TELESCOPICA 220V | E147: 46146 | F147: 390
A148: MARINGA - TERRA DE SANTA CRUZ II | C148: CF MARINGA ALUGUEL DE EQUIPAMENTOS E COMERCIO DE MAQUINAS LT | D148: LOCACAO BOMBA SUBMERSA DE SUCCAO | E148: 46146 | F148: 150
...

Sheet Resumo_Obras
A1: Obra | B1: Valor Total
A2: PORTO RICO - NEO WAVE | B2: =SUMIF([1]Especificação!A:A,A2,[1]Especificação!F:F) -> 47259.718
A3: MARINGA - FORTE DE ATHENA | B3: =SUMIF([1]Especificação!A:A,A3,[1]Especificação!F:F) -> 40226.102
A4: CASCAVEL - DUO VILLE RESIDENCE | B4: =SUMIF([1]Especificação!A:A,A4,[1]Especificação!F:F) -> 202876.53
A5: PAIÇANDU - TERRA DE SANTA CRUZ | B5: =SUMIF([1]Especificação!A:A,A5,[1]Especificação!F:F) -> 29925.973
A6: PARANAVAI - TERRA DE SANTA CRUZ II | B6: =SUMIF([1]Especificação!A:A,A6,[1]Especificação!F:F) -> 226777.76
A7: CASCAVEL - ROYAL PLAZA | B7: =SUMIF([1]Especificação!A:A,A7,[1]Especificação!F:F) -> 328793.19
A8: ARAPONGAS - ROYAL PARADISE | B8: =SUMIF([1]Especificação!A:A,A8,[1]Especificação!F:F) -> 212835.58
A9: MARINGA - FORTE DE ARUNDEL | B9: =SUMIF([1]Especificação!A:A,A9,[1]Especificação!F:F) -> 413033.6
A10: MARINGA - AVALON RESIDENCIAL | B10: =SUMIF([1]Especificação!A:A,A10,[1]Especificação!F:F) -> 38212.74
A11: TOLEDO - ROYAL PARK FOREST | B11: =SUMIF([1]Especificação!A:A,A11,[1]Especificação!F:F) -> 348820.94
A12: MARINGA - TERRA DE SANTA CRUZ II | B12: =SUMIF([1]Especificação!A:A,A12,[1]Especificação!F:F) -> 14779.89
A13: UMUARAMA - ROYAL PORTO DOURADO | B13: =SUMIF([1]Especificação!A:A,A13,[1]Especificação!F:F) -> 48295.87
... A17: MARINGA - ROYAL PALACE | B17: =SUMIF([1]Especificação!A:A,A17,[1]Especificação!F:F) -> 304.2

Sheet Resumo_Coordenadores
A1: Coordenador | B1: Valor Total
A2: Diego Gomes | B2: =SUMIF([1]Especificação!B:B,A2,[1]Especificação!F:F) -> 599993.34
A3: Eduardo Marques | B3: =SUMIF([1]Especificação!B:B,A3,[1]Especificação!F:F) -> 328793.19
A4: Flavia Shigueoka | B4: =SUMIF([1]Especificação!B:B,A4,[1]Especificação!F:F) -> 303963.45
A5: Gustavo Sana | B5: =SUMIF([1]Especificação!B:B,A5,[1]Especificação!F:F) -> 421163.7
A6: Lucas Gaspar | B6: =SUMIF([1]Especificação!B:B,A6,[1]Especificação!F:F) -> 491472.44

Sheet Todos_Insumos
A1: Insumo | B1: Valor Total
A2: MATERIAL PARA EXECUCAO SERVIÇO DE DRYWALL | B2: 315996.65
A3: MATERIAIS DIVERSOS - FATURAMENTO DIRETO | B3: 285212.5
A4: PAVER | B4: 168255
A5: DECORACAO - AMBIENTE PLAYGROUND | B5: 66000
A6: BRITA | B6: 65955.3
A7: MATERIAIS DIVERSOS PARA SERRALHERIA | B7: 52725.84
A8: LOCACAO DE CAMINHAO MUNCK | B8: 43194.004
A9: SERVICO DE EXECUCAO TODAS AS PAREDES EM DRYWALL ST E RU APTOS | B9: 38526.707
A10: BRITA GRADUADA | B10: 36421.398
A11: SERVICOS DE MAO DE OBRA SERRALHERIA | B11: 34780
A12: LOCACAO DE MINI CARREGADEIRA | B12: 29500.608
A13: ACESSORIOS PARA FORMA E SISTEMA DE SEGURANCA | B13: 29498.5
... A543: GUARDANAPO DE PAPEL | B543: 3.9405

Sheet Todos_Fornecedores
A1: Fornecedor | B1: Valor Total
A2: ELG SOLUCOES CONSTRUTIVAS - EIRELI | B2: 251152.8
A3: IVAÍ ARTEFATOS DE CIMENTO LTDA | B3: 160855
A4: M F - EQUIPAMENTOS DE PROTECAO INDIVIDUAL E COLETIVO LTDA | B4: 95099.94
A5: 50.421.151 ANGELA HONORIA DO PRADO | B5: 91448.5
A6: LUCIANO NEVES CRACCO | B6: 88728
A7: M LACHI LOPES COMERCIO DE GESSO LTDA | B7: 80003.344
A8: ART METAL METALURGICA LTDA | B8: 66725
A9: W KATSUMI OGAWA & CIA LTDA | B9: 66000
A10: MATERIAIS DE CONTRUCAO LIDER LTDA | B10: 64146.25
A11: BIGOLIN MATERIAIS DE CONSTRUCAO LTDA | B11: 54615.656
A12: CIB MINERACAO LTDA | B12: 39129
A13: MILENIUM METALURGICA LTDA | B13: 34849
... A208: FERCAM MATERIAIS DE CONSTRUCAO LTDA | B208: 0
